<?xml version="1.0"?>
<robot xmlns:xacro="http://www.ros.org/wiki/xacro" name="example">

<!-- include -->
    <xacro:include filename="gazebo.xacro"/> <!-- for use inertial -->
<!-- link -->

    <xacro:macro name="arm_link" params="prefix">
        <link name="${prefix}">
            <visual>
              <origin rpy="0 0 0" xyz="0 0 0"/>
              <geometry>
                <mesh filename="file:///$(find dummy_description)/meshes/${prefix}.stl"/>
              </geometry>
            </visual>
            
            <collision>
              <geometry>
                <mesh filename="file:///$(find dummy_description)/meshes/${prefix}.stl"/>
              </geometry>
            </collision>

            <xacro:inertial_box mass="10.5" x="0.3" y="0.3" z="0.15">
                <origin xyz="0.15 0 0.075" rpy="0 0 0"/>
            </xacro:inertial_box>

          </link>
    </xacro:macro>


    <link name="world"></link>
    <xacro:arm_link prefix="link_0"/>
    <xacro:arm_link prefix="link_1"/>
    <xacro:arm_link prefix="link_2"/>
    <xacro:arm_link prefix="link_3"/>
    <xacro:arm_link prefix="end_effector"/>

<!-- joint -->

    <joint name="base_joint" type="fixed">
        <parent link="world" /> 
        <child link="link_0" />
        <origin xyz="0 0 0" rpy="0 0 0" />
    </joint>

    <joint name="joint_1" type="revolute">
        <parent link="link_0" /> 
        <child link="link_1" />
        <origin xyz="0 0 0.24" rpy="0 0 0" />
        <axis xyz="0 0 1" />
        <limit effort="1000.0" lower="${-pi}" upper="${pi}" velocity="1000.0" />
        <!-- <dynamic damping="0.1" friction="0.05" /> -->
    </joint>

    <joint name="joint_2" type="revolute">
        <parent link="link_1" /> 
        <child link="link_2" />
        <origin xyz="0 -0.12 0" rpy="${-pi/2} ${-pi/2} 0" />
        <axis xyz="0 0 1" />
        <limit effort="1000.0" lower="${-pi}" upper="${pi}" velocity="1000.0" />
        <!-- <dynamic damping="0.1" friction="0.05" /> -->
    </joint>

    <joint name="joint_3" type="revolute">
        <parent link="link_2" /> 
        <child link="link_3" />
        <origin xyz="0.25 0 0.10" rpy="0 0 0" />
        <axis xyz="0 0 1" />
        <limit effort="1000.0" lower="${-pi}" upper="${pi}" velocity="1000.0" />
        <!-- <dynamic damping="0.1" friction="0.05" /> -->
    </joint>

    <joint name="joint_end_effector" type="fixed">
        <parent link="link_3" /> 
        <child link="end_effector" />
        <origin xyz="0.280 0 0" rpy="${pi/2} 0 ${pi/2}" />
        <!-- <dynamic damping="0.1" friction="0.05" /> -->
    </joint>

</robot>
