<?xml version="1.0"?>
<robot xmlns:xacro="http://www.ros.org/wiki/xacro" name="example">

<!-- variable -->
    <xacro:property name="arm_base_length" value="0.1" />

<!-- link -->

    <xacro:macro name="arm_link" params="prefix">
        <link name="${prefix}">
            <visual>
              <origin rpy="0 0 0" xyz="0 0 0"/>
              <geometry>
                <mesh filename="package://example_description/meshes/${prefix}.stl"/>
              </geometry>
            </visual>
          </link>
    </xacro:macro>

    <xacro:arm_link prefix="link_0"/>
    <xacro:arm_link prefix="link_1"/>
    <xacro:arm_link prefix="link_2"/>
    <xacro:arm_link prefix="link_3"/>
    <xacro:arm_link prefix="end_effector"/>

<!-- joint -->

    <joint name="link_0_link_1" type="revolute">
        <parent link="link_0" /> 
        <child link="link_1" />
        <origin xyz="0 0 0.24" rpy="0 0 0" />
        <axis xyz="0 0 1" />
        <limit effort="100" lower="${-pi}" upper="${pi}" velocity="100" />
        <dynamic damping="0.1" friction="0.05" />
    </joint>

    <joint name="link_1_link_2" type="revolute">
        <parent link="link_1" /> 
        <child link="link_2" />
        <origin xyz="0 -0.12 0" rpy="${-pi/2} ${-pi/2} 0" />
        <axis xyz="0 0 1" />
        <limit effort="100" lower="${-pi}" upper="${pi}" velocity="100" />
        <dynamic damping="0.1" friction="0.05" />
    </joint>

    <joint name="link_2_link_3" type="revolute">
        <parent link="link_2" /> 
        <child link="link_3" />
        <origin xyz="0.25 0 0.10" rpy="0 0 0" />
        <axis xyz="0 0 1" />
        <limit effort="100" lower="${-pi}" upper="${pi}" velocity="100" />
        <dynamic damping="0.1" friction="0.05" />
    </joint>

    <joint name="link_3_end_effector" type="revolute">
        <parent link="link_3" /> 
        <child link="end_effector" />
        <origin xyz="0.280 0 0" rpy="${pi/2} 0 ${pi/2}" />
        <axis xyz="0 0 1" />
        <limit effort="100" lower="${-pi}" upper="${pi}" velocity="100" />
        <dynamic damping="0.1" friction="0.05" />
    </joint>

</robot>
