<?xml version="1.0"?> <!-- This is for VS code recongized as XML files -->

<!-- robot tag -->

 <!-- robot name -->
<robot name="my_robot">   <!-- start -->

    <!--  create material tag for change color -->
    <material name="blue">
        <color rgba="0 0 0.5 1" /> <!-- a = transparency(1 = no transparency) (each value be a number between 0-1) -->
    </material>
    <material name="grey">
        <color rgba="0.5 0.5 0.5 1" /> 
    </material>
    
<!-- //////////////////////////////////////////////////////////////////////////////////////////////////////////// -->

    <!-- create base link(rigit part) -->
    <link name="base_link">
        <visual>
        <geometry>

            <!-- create shape of link (meters) -->
            <box size="0.6 0.4 0.2" /> <!-- size = "long wide high" -->

        </geometry>

        <!-- create origin of visual for xyz in translation and rpy in rotation -->
        <origin xyz="0 0 0.1" rpy="0 0 0" /> <!-- z = +0.1 for lifted link to on the ground -->

        <!-- change color -->
            <material name="blue" />

        </visual>
    </link>

<!-- //////////////////////////////////////////////////////////////////////////////////////////////////////////// -->

    <!-- create second link(rigit part) -->
    <link name="second_link">
    <visual>
        <geometry>

            <!-- create shape of link with cylinder (meters) -->
            <cylinder radius="0.1" length="0.2" />

        </geometry>
        <origin xyz="0 0 0.1" rpy="0 0 0" /> 
        <material name="grey" />
    </visual>
    </link>

<!-- //////////////////////////////////////////////////////////////////////////////////////////////////////////// -->

    <link name="third_link">
        <visual>
        <geometry>
            <box size="0.1 0.1 0.1" />
        </geometry>
        <origin xyz="0 0 0.05" rpy="0 0 0" /> 
            <material name="blue" />
        </visual>
    </link>

<!-- //////////////////////////////////////////////////////////////////////////////////////////////////////////// -->

    <link name="fourth_link">
        <visual>
        <geometry>
            <box size="0.1 0.1 0.1" />
        </geometry>
        <origin xyz="0 0 0.05" rpy="0 0 0" /> 
            <material name="grey" />
        </visual>
    </link>

<!-- //////////////////////////////////////////////////////////////////////////////////////////////////////////// -->


    <link name="fifth_link">
        <visual>
            <geometry>
    
                <!-- create shape of link with cylinder (meters) -->
                <cylinder radius="0.025" length="0.1" />
    
            </geometry>
            <origin xyz="0 0 0.1" rpy="0 0 0" /> 
            <material name="blue" />
        </visual>
        </link>

<!-- //////////////////////////////////////////////////////////////////////////////////////////////////////////// -->

    <!-- create joint for pair link -->
    <joint name="base_second_joint" type="fixed"> <!-- "fixed" = two links are pair but not move -->

        <!-- set connection of joint -->
        <parent link="base_link" /> <!-- base_link owns this joint -->
        <child link="second_link" />

        <!-- origin of joint -->
        <origin xyz="0 0 0.2" rpy="0 0 0" /> <!-- recommend to put 0 in origin first time every link and joint, then fix later-->
    </joint>   

<!-- //////////////////////////////////////////////////////////////////////////////////////////////////////////// -->

    <joint name="second_third_joint" type="revolute"> <!-- see mean of type in google "urdf/xml" -->
        <parent link="second_link" /> 
        <child link="third_link" />
        <origin xyz="0 0 0.2" rpy="0 0 0" /> 
        <!-- for revolute type -->
        <axis xyz="0 0 1" /> <!-- rotation on z axis but no rotation on x,y axis -->
        <limit lower="-1.57" upper="1.57" velocity="100" effort="100"/> <!-- lower = minimum of angle(radian) (-1.57 radian = -90 degree)-->
                                                                        <!-- upper = maximum of angle(radian) -->
                                                                        <!-- velo and effort are not to be consider now but you can see what mean in google -->
    </joint>    

<!-- //////////////////////////////////////////////////////////////////////////////////////////////////////////// -->

    <joint name="third_fourth_joint" type="continuous"> <!-- same as revolute but no limit (recommend use in wheel) -->
        <parent link="third_link" /> 
        <child link="fourth_link" />
        <origin xyz="0 0 0.1" rpy="0 0 0" /> 
        <!-- for continuous type -->
        <axis xyz="0 1 0" /> <!-- rotation on y axis but no rotation on x,z axis -->
        
    </joint> 

<!-- //////////////////////////////////////////////////////////////////////////////////////////////////////////// -->

    <joint name="fourth_fifth_joint" type="prismatic"> <!-- sliding joint -->
        <parent link="fourth_link" /> 
        <child link="fifth_link" />
        <origin xyz="0 0 0.05" rpy="0 0 0" /> 
        <!-- for prismatic type -->
        <axis xyz="1 0 0" /> <!-- slide on x axis but no slide on y,z axis -->
        <limit lower="-0.025" upper="0.025" velocity="100" effort="100"/>   <!-- lower = minimum of distance to slide(meters) -->
                                                                            <!-- upper = maximum of distance to slide(meters) -->
        
    </joint>

</robot> <!-- stop -->